Workbook

Sheet New Matches
B1: Job Details | J1: Match Details (from PF Export: Project Report)
A2: Key - Job Code | B2: Job Family | C2: Job Sub-Family | D2: Date | E2: Job Level | F2: Current Job Title | G2: New Job Title | H2: Key | I2: Job Code | J2: Job Title | K2: Job Code | L2: Source | M2: Scope | N2: Curr | O2: Base 25th | P2: Base 50th | Q2: Base 75th | R2: AZL Avg | S2: AZL % | T2: TCC 25th | U2: TCC 50th | V2: TCC 75th | W2: Avg Base | X2: Base to Market | Y2: Avg Base to Market | Z2: Inc Count | AA2: Comment
A3: =I3 -> AR-AR-M2-2 | B3: Actuarial | C3: Actuarial | D3: 45715 | E3: M2 | F3: =IFERROR(VLOOKUP(I3, 'Job Code Table'!D:E, 2, FALSE), "") | G3: =VLOOKUP(I3, '[1]Job Mapping'!$B:$N, 13, FALSE) -> Assistant Actuary | H3: =_xlfn.CONCAT(E3, "-", G3) -> M2-Assistant Actuary | I3: AR-AR-M2-2 | J3: Supervising Actuary | K3: 401 | L3: ClearSolutionsHR: Life/Health Actuarial Salary Survey 04/01/2024 | M3: Life & Health/all/ | N3: USD | O3: 161.7 | P3: 175.9 | Q3: 190.2 | T3: 191.3 | U3: 211.7 | V3: 235.4 | W3: =IFERROR(VLOOKUP(I3, Summary!K:L, 2, FALSE), "") | X3: =IF(W3="","",W3/P3) | Y3: =IFERROR(ROUND(VLOOKUP(I3, Summary!K:L, 2, FALSE)/VLOOKUP(I3, Summary!N:O, 2, FALSE), 1), "") | Z3: =IFERROR(VLOOKUP(I3, Summary!Q:R, 2, FALSE), 0) -> 0
A4: =I4 -> AR-AR-M2-2 | B4: Actuarial | C4: Actuarial | D4: 45715 | E4: M2 | F4: =IFERROR(VLOOKUP(I4, 'Job Code Table'!D:E, 2, FALSE), "") | G4: =VLOOKUP(I4, '[1]Job Mapping'!$B:$N, 13, FALSE) -> Assistant Actuary | H4: =_xlfn.CONCAT(E4, "-", G4) -> M2-Assistant Actuary | I4: AR-AR-M2-2 | J4: Actuary | K4: 5024 | L4: Corporate Comp Strategies: Life Survey Group 03/01/2024 | M4: All// | N4: USD | O4: 151.8 | P4: 165.1 | Q4: 181.4 | T4: 175.3 | U4: 195.7 | V4: 221.3 | W4: =IFERROR(VLOOKUP(I4, Summary!K:L, 2, FALSE), "") | X4: =IF(W4="","",W4/P4) | Y4: =IFERROR(ROUND(VLOOKUP(I4, Summary!K:L, 2, FALSE)/VLOOKUP(I4, Summary!N:O, 2, FALSE), 1), "") | Z4: =IFERROR(VLOOKUP(I4, Summary!Q:R, 2, FALSE), 0) -> 0
A5: =I5 -> AR-AR-M2-2 | B5: Actuarial | C5: Actuarial | D5: 45715 | E5: M2 | F5: =IFERROR(VLOOKUP(I5, 'Job Code Table'!D:E, 2, FALSE), "") | G5: =VLOOKUP(I5, '[1]Job Mapping'!$B:$N, 13, FALSE) -> Assistant Actuary | H5: =_xlfn.CONCAT(E5, "-", G5) -> M2-Assistant Actuary | I5: AR-AR-M2-2 | J5: Associate Actuary | K5: 2103 | L5: Life Office Management Assoc: Non-Executive Compensation Survey 04/01/2024 | M5: All Companies/All Companies/ | N5: USD | O5: 147 | P5: 159.3 | Q5: 176.7 | T5: 167 | U5: 187.4 | V5: 209.2 | W5: =IFERROR(VLOOKUP(I5, Summary!K:L, 2, FALSE), "") | X5: =IF(W5="","",W5/P5) | Y5: =IFERROR(ROUND(VLOOKUP(I5, Summary!K:L, 2, FALSE)/VLOOKUP(I5, Summary!N:O, 2, FALSE), 1), "") | Z5: =IFERROR(VLOOKUP(I5, Summary!Q:R, 2, FALSE), 0) -> 0
A6: =I6 -> AR-AR-M2-2 | B6: Actuarial | C6: Actuarial | D6: 45715 | E6: M2 | F6: =IFERROR(VLOOKUP(I6, 'Job Code Table'!D:E, 2, FALSE), "") | G6: =VLOOKUP(I6, '[1]Job Mapping'!$B:$N, 13, FALSE) -> Assistant Actuary | H6: =_xlfn.CONCAT(E6, "-", G6) -> M2-Assistant Actuary | I6: AR-AR-M2-2 | J6: Actuarial - Life|Actuarial - Life Generalist/Multidiscipline|Manager (Supervisory/Management)-M2-All Incumbent Global Grade | K6: FAD000-M2 | L6: Towers Watson: Financial Services MMPS 04/01/2024 | M6: Total Sample// | N6: USD | O6: 139.6 | P6: 162.1 | Q6: 176 | T6: 162.8 | U6: 186.1 | V6: 209.2 | W6: =IFERROR(VLOOKUP(I6, Summary!K:L, 2, FALSE), "") | X6: =IF(W6="","",W6/P6) | Y6: =IFERROR(ROUND(VLOOKUP(I6, Summary!K:L, 2, FALSE)/VLOOKUP(I6, Summary!N:O, 2, FALSE), 1), "") | Z6: =IFERROR(VLOOKUP(I6, Summary!Q:R, 2, FALSE), 0) -> 0
A7: =I7 -> AR-AR-M2-1 | B7: Actuarial | C7: Actuarial | D7: 45715 | E7: M2 | F7: =IFERROR(VLOOKUP(I7, 'Job Code Table'!D:E, 2, FALSE), "") | G7: =VLOOKUP(I7, '[1]Job Mapping'!$B:$N, 13, FALSE) -> Associate Actuary | H7: =_xlfn.CONCAT(E7, "-", G7) -> M2-Associate Actuary | I7: AR-AR-M2-1 | J7: Supervising Actuary | K7: 401 | L7: ClearSolutionsHR: Life/Health Actuarial Salary Survey 04/01/2024 | M7: Life & Health/all/ | N7: USD | O7: 161.7 | P7: 175.9 | Q7: 190.2 | T7: 191.3 | U7: 211.7 | V7: 235.4 | W7: =IFERROR(VLOOKUP(I7, Summary!K:L, 2, FALSE), "") | X7: =IF(W7="","",W7/P7) | Y7: =IFERROR(ROUND(VLOOKUP(I7, Summary!K:L, 2, FALSE)/VLOOKUP(I7, Summary!N:O, 2, FALSE), 1), "") | Z7: =IFERROR(VLOOKUP(I7, Summary!Q:R, 2, FALSE), 0) -> 0
A8: =I8 -> AR-AR-M2-1 | B8: Actuarial | C8: Actuarial | D8: 45715 | E8: M2 | F8: =IFERROR(VLOOKUP(I8, 'Job Code Table'!D:E, 2, FALSE), "") | G8: =VLOOKUP(I8, '[1]Job Mapping'!$B:$N, 13, FALSE) -> Associate Actuary | H8: =_xlfn.CONCAT(E8, "-", G8) -> M2-Associate Actuary | I8: AR-AR-M2-1 | J8: Actuary | K8: 5024 | L8: Corporate Comp Strategies: Life Survey Group 03/01/2024 | M8: All// | N8: USD | O8: 151.8 | P8: 165.1 | Q8: 181.4 | T8: 175.3 | U8: 195.7 | V8: 221.3 | W8: =IFERROR(VLOOKUP(I8, Summary!K:L, 2, FALSE), "") | X8: =IF(W8="","",W8/P8) | Y8: =IFERROR(ROUND(VLOOKUP(I8, Summary!K:L, 2, FALSE)/VLOOKUP(I8, Summary!N:O, 2, FALSE), 1), "") | Z8: =IFERROR(VLOOKUP(I8, Summary!Q:R, 2, FALSE), 0) -> 0
A9: =I9 -> AR-AR-M2-1 | B9: Actuarial | C9: Actuarial | D9: 45715 | E9: M2 | F9: =IFERROR(VLOOKUP(I9, 'Job Code Table'!D:E, 2, FALSE), "") | G9: =VLOOKUP(I9, '[1]Job Mapping'!$B:$N, 13, FALSE) -> Associate Actuary | H9: =_xlfn.CONCAT(E9, "-", G9) -> M2-Associate Actuary | I9: AR-AR-M2-1 | J9: Assistant Actuary | K9: 2104 | L9: Life Office Management Assoc: Non-Executive Compensation Survey 04/01/2024 | M9: All Companies/All Companies/ | N9: USD | O9: 141.7 | P9: 155.3 | Q9: 166.5 | T9: 158.3 | U9: 172.5 | V9: 187.2 | W9: =IFERROR(VLOOKUP(I9, Summary!K:L, 2, FALSE), "") | X9: =IF(W9="","",W9/P9) | Y9: =IFERROR(ROUND(VLOOKUP(I9, Summary!K:L, 2, FALSE)/VLOOKUP(I9, Summary!N:O, 2, FALSE), 1), "") | Z9: =IFERROR(VLOOKUP(I9, Summary!Q:R, 2, FALSE), 0) -> 0
A10: =I10 -> AR-AR-M2-1 | B10: Actuarial | C10: Actuarial | D10: 45715 | E10: M2 | F10: =IFERROR(VLOOKUP(I10, 'Job Code Table'!D:E, 2, FALSE), "") | G10: =VLOOKUP(I10, '[1]Job Mapping'!$B:$N, 13, FALSE) -> Associate Actuary | H10: =_xlfn.CONCAT(E10, "-", G10) -> M2-Associate Actuary | I10: AR-AR-M2-1 | J10: Actuarial - Life|Actuarial - Life Generalist/Multidiscipline|Manager (Supervisory/Management)-M2-All Incumbent Global Grade | K10: FAD000-M2 | L10: Towers Watson: Financial Services MMPS 04/01/2024 | M10: Total Sample// | N10: USD | O10: 139.6 | P10: 162.1 | Q10: 176 | T10: 162.8 | U10: 186.1 | V10: 209.2 | W10: =IFERROR(VLOOKUP(I10, Summary!K:L, 2, FALSE), "") | X10: =IF(W10="","",W10/P10) | Y10: =IFERROR(ROUND(VLOOKUP(I10, Summary!K:L, 2, FALSE)/VLOOKUP(I10, Summary!N:O, 2, FALSE), 1), "") | Z10: =IFERROR(VLOOKUP(I10, Summary!Q:R, 2, FALSE), 0) -> 0
A11: =I11 -> AR-AR-M3-1 | B11: Actuarial | C11: Actuarial | D11: 45715 | E11: M3 | G11: =VLOOKUP(I11, '[1]Job Mapping'!$B:$N, 13, FALSE) -> Actuary | H11: =_xlfn.CONCAT(E11, "-", G11) -> M3-Actuary | I11: AR-AR-M3-1 | J11: Managing Actuary - Consolidated | K11: 300 | L11: ClearSolutionsHR: Life/Health Actuarial Salary Survey 04/01/2024 | M11: Life & Health/all/ | N11: USD | O11: 184.9 | P11: 206.5 | Q11: 229.1 | T11: 217.2 | U11: 256.5 | V11: 296.6 | W11: =IFERROR(VLOOKUP(I11, Summary!K:L, 2, FALSE), "") | X11: =IF(W11="","",W11/P11) | Y11: =IFERROR(ROUND(VLOOKUP(I11, Summary!K:L, 2, FALSE)/VLOOKUP(I11, Summary!N:O, 2, FALSE), 1), "") | Z11: =IFERROR(VLOOKUP(I11, Summary!Q:R, 2, FALSE), 0) -> 0
A12: =I12 -> AR-AR-M3-1 | B12: Actuarial | C12: Actuarial | D12: 45715 | E12: M3 | G12: =VLOOKUP(I12, '[1]Job Mapping'!$B:$N, 13, FALSE) -> Actuary | H12: =_xlfn.CONCAT(E12, "-", G12) -> M3-Actuary | I12: AR-AR-M3-1 | J12: Actuary | K12: 5024 | L12: Corporate Comp Strategies: Life Survey Group 03/01/2024 | M12: All// | N12: USD | O12: 167 | P12: 181.6 | Q12: 199.5 | T12: 192.8 | U12: 215.3 | V12: 243.4 | W12: =IFERROR(VLOOKUP(I12, Summary!K:L, 2, FALSE), "") | X12: =IF(W12="","",W12/P12) | Y12: =IFERROR(ROUND(VLOOKUP(I12, Summary!K:L, 2, FALSE)/VLOOKUP(I12, Summary!N:O, 2, FALSE), 1), "") | Z12: =IFERROR(VLOOKUP(I12, Summary!Q:R, 2, FALSE), 0) -> 0
A13: =I13 -> AR-AR-M3-1 | B13: Actuarial | C13: Actuarial | D13: 45715 | E13: M3 | G13: =VLOOKUP(I13, '[1]Job Mapping'!$B:$N, 13, FALSE) -> Actuary | H13: =_xlfn.CONCAT(E13, "-", G13) -> M3-Actuary | I13: AR-AR-M3-1 | J13: Associate Actuary | K13: 2103 | L13: Life Office Management Assoc: Non-Executive Compensation Survey 04/01/2024 | M13: All Companies/All Companies/ | N13: USD | O13: 147 | P13: 159.3 | Q13: 176.7 | T13: 167 | U13: 187.4 | V13: 209.2 | W13: =IFERROR(VLOOKUP(I13, Summary!K:L, 2, FALSE), "") | X13: =IF(W13="","",W13/P13) | Y13: =IFERROR(ROUND(VLOOKUP(I13, Summary!K:L, 2, FALSE)/VLOOKUP(I13, Summary!N:O, 2, FALSE), 1), "") | Z13: =IFERROR(VLOOKUP(I13, Summary!Q:R, 2, FALSE), 0) -> 0
A14: =I14 -> AR-AR-M3-1 | B14: Actuarial | C14: Actuarial | D14: 45715 | E14: M3 | G14: =VLOOKUP(I14, '[1]Job Mapping'!$B:$N, 13, FALSE) -> Actuary | H14: =_xlfn.CONCAT(E14, "-", G14) -> M3-Actuary | I14: AR-AR-M3-1 | J14: Actuarial - Life|Actuarial - Life Generalist/Multidiscipline|Senior Manager (Supervisory/Management)-M3-All Incumbent Global Grade | K14: FAD000-M3 | L14: Towers Watson: Financial Services MMPS 04/01/2024 | M14: Total Sample// | N14: USD | O14: 168.9 | P14: 184.3 | Q14: 204 | T14: 205.8 | U14: 225.4 | V14: 255.8 | W14: =IFERROR(VLOOKUP(I14, Summary!K:L, 2, FALSE), "") | X14: =IF(W14="","",W14/P14) | Y14: =IFERROR(ROUND(VLOOKUP(I14, Summary!K:L, 2, FALSE)/VLOOKUP(I14, Summary!N:O, 2, FALSE), 1), "") | Z14: =IFERROR(VLOOKUP(I14, Summary!Q:R, 2, FALSE), 0) -> 0
A15: =I15 -> AR-AR-M3-2 | B15: Actuarial | C15: Actuarial | D15: 45715 | E15: M3 | G15: =VLOOKUP(I15, '[1]Job Mapping'!$B:$N, 13, FALSE) -> Senior Actuary | H15: =_xlfn.CONCAT(E15, "-", G15) -> M3-Senior Actuary | I15: AR-AR-M3-2 | J15: Managing Actuary - Consolidated | K15: 300 | L15: ClearSolutionsHR: Life/Health Actuarial Salary Survey 04/01/2024 | M15: Life & Health/all/ | N15: USD | O15: 184.9 | P15: 206.5 | Q15: 229.1 | T15: 217.2 | U15: 256.5 | V15: 296.6 | W15: =IFERROR(VLOOKUP(I15, Summary!K:L, 2, FALSE), "") | X15: =IF(W15="","",W15/P15) | Y15: =IFERROR(ROUND(VLOOKUP(I15, Summary!K:L, 2, FALSE)/VLOOKUP(I15, Summary!N:O, 2, FALSE), 1), "") | Z15: =IFERROR(VLOOKUP(I15, Summary!Q:R, 2, FALSE), 0) -> 0
A16: =I16 -> AR-AR-M3-2 | B16: Actuarial | C16: Actuarial | D16: 45715 | E16: M3 | G16: =VLOOKUP(I16, '[1]Job Mapping'!$B:$N, 13, FALSE) -> Senior Actuary | H16: =_xlfn.CONCAT(E16, "-", G16) -> M3-Senior Actuary | I16: AR-AR-M3-2 | J16: Senior Actuary | K16: 5022 | L16: Corporate Comp Strategies: Life Survey Group 03/01/2024 | M16: All// | N16: USD | O16: 175.2 | P16: 187.6 | Q16: 208.7 | T16: 213.1 | U16: 231.5 | V16: 265 | W16: =IFERROR(VLOOKUP(I16, Summary!K:L, 2, FALSE), "") | X16: =IF(W16="","",W16/P16) | Y16: =IFERROR(ROUND(VLOOKUP(I16, Summary!K:L, 2, FALSE)/VLOOKUP(I16, Summary!N:O, 2, FALSE), 1), "") | Z16: =IFERROR(VLOOKUP(I16, Summary!Q:R, 2, FALSE), 0) -> 0
A17: =I17 -> AR-AR-M3-2 | B17: Actuarial | C17: Actuarial | D17: 45715 | E17: M3 | G17: =VLOOKUP(I17, '[1]Job Mapping'!$B:$N, 13, FALSE) -> Senior Actuary | H17: =_xlfn.CONCAT(E17, "-", G17) -> M3-Senior Actuary | I17: AR-AR-M3-2 | J17: Actuary | K17: 2102 | L17: Life Office Management Assoc: Non-Executive Compensation Survey 04/01/2024 | M17: All Companies/All Companies/ | N17: USD | O17: 187.7 | P17: 201.4 | Q17: 221.3 | T17: 225.4 | U17: 246.8 | V17: 274 | W17: =IFERROR(VLOOKUP(I17, Summary!K:L, 2, FALSE), "") | X17: =IF(W17="","",W17/P17) | Y17: =IFERROR(ROUND(VLOOKUP(I17, Summary!K:L, 2, FALSE)/VLOOKUP(I17, Summary!N:O, 2, FALSE), 1), "") | Z17: =IFERROR(VLOOKUP(I17, Summary!Q:R, 2, FALSE), 0) -> 0
A18: =I18 -> AR-AR-M3-2 | B18: Actuarial | C18: Actuarial | D18: 45715 | E18: M3 | G18: =VLOOKUP(I18, '[1]Job Mapping'!$B:$N, 13, FALSE) -> Senior Actuary | H18: =_xlfn.CONCAT(E18, "-", G18) -> M3-Senior Actuary | I18: AR-AR-M3-2 | J18: Actuarial - Life|Actuarial - Life Generalist/Multidiscipline|Senior Manager (Supervisory/Management)-M3-All Incumbent Global Grade | K18: FAD000-M3 | L18: Towers Watson: Financial Services MMPS 04/01/2024 | M18: Total Sample// | N18: USD | O18: 168.9 | P18: 184.3 | Q18: 204 | T18: 205.8 | U18: 225.4 | V18: 255.8 | W18: =IFERROR(VLOOKUP(I18, Summary!K:L, 2, FALSE), "") | X18: =IF(W18="","",W18/P18) | Y18: =IFERROR(ROUND(VLOOKUP(I18, Summary!K:L, 2, FALSE)/VLOOKUP(I18, Summary!N:O, 2, FALSE), 1), "") | Z18: =IFERROR(VLOOKUP(I18, Summary!Q:R, 2, FALSE), 0) -> 0
A19: =I19 -> 100811 | B19: Actuarial | C19: Actuarial | D19: 45715 | E19: M4 | G19: =VLOOKUP(I19, '[1]Job Mapping'!$B:$N, 13, FALSE) -> Senior Director Actuary | H19: =_xlfn.CONCAT(E19, "-", G19) -> M4-Senior Director Actuary | I19: 100811 | J19: Managing Actuary - Consolidated | K19: 300 | L19: ClearSolutionsHR: Life/Health Actuarial Salary Survey 04/01/2024 | M19: Life & Health/all/ | N19: USD | O19: 184.9 | P19: 206.5 | Q19: 229.1 | T19: 217.2 | U19: 256.5 | V19: 296.6 | W19: =IFERROR(VLOOKUP(I19, Summary!K:L, 2, FALSE), "") -> 226.9 | X19: =IF(W19="","",W19/P19) -> 1.0987893 | Y19: =IFERROR(ROUND(VLOOKUP(I19, Summary!K:L, 2, FALSE)/VLOOKUP(I19, Summary!N:O, 2, FALSE), 1), "") -> 1.1 | Z19: =IFERROR(VLOOKUP(I19, Summary!Q:R, 2, FALSE), 0) -> 4
A20: =I20 -> 100811 | B20: Actuarial | C20: Actuarial | D20: 45715 | E20: M4 | G20: =VLOOKUP(I20, '[1]Job Mapping'!$B:$N, 13, FALSE) -> Senior Director Actuary | H20: =_xlfn.CONCAT(E20, "-", G20) -> M4-Senior Director Actuary | I20: 100811 | J20: Managing Actuary | K20: 5010 | L20: Corporate Comp Strategies: Life Survey Group 03/01/2024 | M20: All// | N20: USD | O20: 185 | P20: 205.5 | Q20: 228.5 | T20: 219.4 | U20: 262.8 | V20: 302.6 | W20: =IFERROR(VLOOKUP(I20, Summary!K:L, 2, FALSE), "") -> 226.9 | X20: =IF(W20="","",W20/P20) -> 1.1041363 | Y20: =IFERROR(ROUND(VLOOKUP(I20, Summary!K:L, 2, FALSE)/VLOOKUP(I20, Summary!N:O, 2, FALSE), 1), "") -> 1.1 | Z20: =IFERROR(VLOOKUP(I20, Summary!Q:R, 2, FALSE), 0) -> 4
A21: =I21 -> 100811 | B21: Actuarial | C21: Actuarial | D21: 45715 | E21: M4 | G21: =VLOOKUP(I21, '[1]Job Mapping'!$B:$N, 13, FALSE) -> Senior Director Actuary | H21: =_xlfn.CONCAT(E21, "-", G21) -> M4-Senior Director Actuary | I21: 100811 | J21: Managing Actuary | K21: 2101 | L21: Life Office Management Assoc: Non-Executive Compensation Survey 04/01/2024 | M21: All Companies/All Companies/ | N21: USD | O21: 196.9 | P21: 213.2 | Q21: 239.1 | T21: 230.5 | U21: 265.2 | V21: 303.2 | W21: =IFERROR(VLOOKUP(I21, Summary!K:L, 2, FALSE), "") -> 226.9 | X21: =IF(W21="","",W21/P21) -> 1.0642589 | Y21: =IFERROR(ROUND(VLOOKUP(I21, Summary!K:L, 2, FALSE)/VLOOKUP(I21, Summary!N:O, 2, FALSE), 1), "") -> 1.1 | Z21: =IFERROR(VLOOKUP(I21, Summary!Q:R, 2, FALSE), 0) -> 4
A22: =I22 -> 100811 | B22: Actuarial | C22: Actuarial | D22: 45715 | E22: M4 | G22: =VLOOKUP(I22, '[1]Job Mapping'!$B:$N, 13, FALSE) -> Senior Director Actuary | H22: =_xlfn.CONCAT(E22, "-", G22) -> M4-Senior Director Actuary | I22: 100811 | J22: Actuarial - Life|Actuarial - Life Generalist/Multidiscipline|Group Manager (Supervisory/Management)-M4-All Incumbent Global Grade | K22: FAD000-M4 | L22: Towers Watson: Financial Services MMPS 04/01/2024 | M22: Total Sample// | N22: USD | O22: 215.1 | P22: 232.8 | Q22: 249.3 | T22: 269.5 | U22: 306 | V22: 343.7 | W22: =IFERROR(VLOOKUP(I22, Summary!K:L, 2, FALSE), "") -> 226.9 | X22: =IF(W22="","",W22/P22) -> 0.97465636 | Y22: =IFERROR(ROUND(VLOOKUP(I22, Summary!K:L, 2, FALSE)/VLOOKUP(I22, Summary!N:O, 2, FALSE), 1), "") -> 1.1 | Z22: =IFERROR(VLOOKUP(I22, Summary!Q:R, 2, FALSE), 0) -> 4
A23: =I23 -> 100024 | B23: Actuarial | C23: Actuarial | D23: 45715 | E23: P1 | F23: =IFERROR(VLOOKUP(I23, 'Job Code Table'!D:E, 2, FALSE), "") -> Actuarial Analyst | G23: =VLOOKUP(I23, '[1]Job Mapping'!$B:$N, 13, FALSE) -> Actuarial Analyst | H23: =_xlfn.CONCAT(E23, "-", G23) -> P1-Actuarial Analyst | I23: 100024 | J23: Level I - Entry Actuarial Candidate | K23: 505 | L23: ClearSolutionsHR: Life/Health Actuarial Salary Survey 04/01/2024 | M23: Life & Health/all/ | N23: USD | O23: 78.1 | P23: 83.1 | Q23: 88.5 | T23: 81 | U23: 86.3 | V23: 93.1 | W23: =IFERROR(VLOOKUP(I23, Summary!K:L, 2, FALSE), "") -> 91.613333 | X23: =IF(W23="","",W23/P23) -> 1.1024469 | Y23: =IFERROR(ROUND(VLOOKUP(I23, Summary!K:L, 2, FALSE)/VLOOKUP(I23, Summary!N:O, 2, FALSE), 1), "") -> 1 | Z23: =IFERROR(VLOOKUP(I23, Summary!Q:R, 2, FALSE), 0) -> 15 | AA23: 1-3 exams
A24: =I24 -> 100024 | B24: Actuarial | C24: Actuarial | D24: 45715 | E24: P1 | F24: =IFERROR(VLOOKUP(I24, 'Job Code Table'!D:E, 2, FALSE), "") -> Actuarial Analyst | G24: =VLOOKUP(I24, '[1]Job Mapping'!$B:$N, 13, FALSE) -> Actuarial Analyst | H24: =_xlfn.CONCAT(E24, "-", G24) -> P1-Actuarial Analyst | I24: 100024 | J24: Actuarial Analyst | K24: 5034 | L24: Corporate Comp Strategies: Life Survey Group 03/01/2024 | M24: All// | N24: USD | O24: 82.5 | P24: 90.4 | Q24: 102 | T24: 85.8 | U24: 95.4 | V24: 108.7 | W24: =IFERROR(VLOOKUP(I24, Summary!K:L, 2, FALSE), "") -> 91.613333 | X24: =IF(W24="","",W24/P24) -> 1.0134218 | Y24: =IFERROR(ROUND(VLOOKUP(I24, Summary!K:L, 2, FALSE)/VLOOKUP(I24, Summary!N:O, 2, FALSE), 1), "") -> 1 | Z24: =IFERROR(VLOOKUP(I24, Summary!Q:R, 2, FALSE), 0) -> 15 | AA24: 1-3 exams
A25: =I25 -> 100024 | B25: Actuarial | C25: Actuarial | D25: 45715 | E25: P1 | F25: =IFERROR(VLOOKUP(I25, 'Job Code Table'!D:E, 2, FALSE), "") -> Actuarial Analyst | G25: =VLOOKUP(I25, '[1]Job Mapping'!$B:$N, 13, FALSE) -> Actuarial Analyst | H25: =_xlfn.CONCAT(E25, "-", G25) -> P1-Actuarial Analyst | I25: 100024 | J25: Actuarial Analyst | K25: 2106 | L25: Life Office Management Assoc: Non-Executive Compensation Survey 04/01/2024 | M25: All Companies/All Companies/ | N25: USD | O25: 89.4 | P25: 98.1 | Q25: 105.6 | T25: 95.1 | U25: 103.8 | V25: 112.8 | W25: =IFERROR(VLOOKUP(I25, Summary!K:L, 2, FALSE), "") -> 91.613333 | X25: =IF(W25="","",W25/P25) -> 0.933877 | Y25: =IFERROR(ROUND(VLOOKUP(I25, Summary!K:L, 2, FALSE)/VLOOKUP(I25, Summary!N:O, 2, FALSE), 1), "") -> 1 | Z25: =IFERROR(VLOOKUP(I25, Summary!Q:R, 2, FALSE), 0) -> 15 | AA25: 1-3 exams
A26: =I26 -> 100024 | B26: Actuarial | C26: Actuarial | D26: 45715 | E26: P1 | F26: =IFERROR(VLOOKUP(I26, 'Job Code Table'!D:E, 2, FALSE), "") -> Actuarial Analyst | G26: =VLOOKUP(I26, '[1]Job Mapping'!$B:$N, 13, FALSE) -> Actuarial Analyst | H26: =_xlfn.CONCAT(E26, "-", G26) -> P1-Actuarial Analyst | I26: 100024 | J26: Actuarial - Life|Actuarial - Life Generalist/Multidiscipline|Entry (Professional)-P1-All Incumbent Global Grade | K26: FAD000-P1 | L26: Towers Watson: Financial Services MMPS 04/01/2024 | M26: Total Sample// | N26: USD | O26: 76.3 | P26: 81.8 | Q26: 88.2 | T26: 80.7 | U26: 87.8 | V26: 94.7 | W26: =IFERROR(VLOOKUP(I26, Summary!K:L, 2, FALSE), "") -> 91.613333 | X26: =IF(W26="","",W26/P26) -> 1.1199674 | Y26: =IFERROR(ROUND(VLOOKUP(I26, Summary!K:L, 2, FALSE)/VLOOKUP(I26, Summary!N:O, 2, FALSE), 1), "") -> 1 | Z26: =IFERROR(VLOOKUP(I26, Summary!Q:R, 2, FALSE), 0) -> 15 | AA26: 1-3 exams
A27: =I27 -> 100702 | B27: Actuarial | C27: Actuarial | D27: 45715 | E27: P2 | F27: =IFERROR(VLOOKUP(I27, 'Job Code Table'!D:E, 2, FALSE), "") -> Principal Actuarial Analyst | G27: =VLOOKUP(I27, '[1]Job Mapping'!$B:$N, 13, FALSE) -> Principal Actuarial Analyst | H27: =_xlfn.CONCAT(E27, "-", G27) -> P2-Principal Actuarial Analyst | I27: 100702 | J27: Level III - Senior Actuarial Assistant | K27: 503 | L27: ClearSolutionsHR: Life/Health Actuarial Salary Survey 04/01/2024 | M27: Life & Health/all/ | N27: USD | O27: 113 | P27: 123 | Q27: 133.3 | T27: 122.4 | U27: 134.4 | V27: 146.4 | W27: =IFERROR(VLOOKUP(I27, Summary!K:L, 2, FALSE), "") -> 123.31875 | X27: =IF(W27="","",W27/P27) -> 1.0025915 | Y27: =IFERROR(ROUND(VLOOKUP(I27, Summary!K:L, 2, FALSE)/VLOOKUP(I27, Summary!N:O, 2, FALSE), 1), "") -> 1 | Z27: =IFERROR(VLOOKUP(I27, Summary!Q:R, 2, FALSE), 0) -> 16 | AA27: 5-6 exams/ASA
A28: =I28 -> 100702 | B28: Actuarial | C28: Actuarial | D28: 45715 | E28: P2 | F28: =IFERROR(VLOOKUP(I28, 'Job Code Table'!D:E, 2, FALSE), "") -> Principal Actuarial Analyst | G28: =VLOOKUP(I28, '[1]Job Mapping'!$B:$N, 13, FALSE) -> Principal Actuarial Analyst | H28: =_xlfn.CONCAT(E28, "-", G28) -> P2-Principal Actuarial Analyst | I28: 100702 | J28: Actuarial Associate | K28: 5026 | L28: Corporate Comp Strategies: Life Survey Group 03/01/2024 | M28: All// | N28: USD | O28: 121.1 | P28: 133.7 | Q28: 147.9 | T28: 134.5 | U28: 151.6 | V28: 170.7 | W28: =IFERROR(VLOOKUP(I28, Summary!K:L, 2, FALSE), "") -> 123.31875 | X28: =IF(W28="","",W28/P28) -> 0.92235415 | Y28: =IFERROR(ROUND(VLOOKUP(I28, Summary!K:L, 2, FALSE)/VLOOKUP(I28, Summary!N:O, 2, FALSE), 1), "") -> 1 | Z28: =IFERROR(VLOOKUP(I28, Summary!Q:R, 2, FALSE), 0) -> 16 | AA28: 5-6 exams/ASA
A29: =I29 -> 100702 | B29: Actuarial | C29: Actuarial | D29: 45715 | E29: P2 | F29: =IFERROR(VLOOKUP(I29, 'Job Code Table'!D:E, 2, FALSE), "") -> Principal Actuarial Analyst | G29: =VLOOKUP(I29, '[1]Job Mapping'!$B:$N, 13, FALSE) -> Principal Actuarial Analyst | H29: =_xlfn.CONCAT(E29, "-", G29) -> P2-Principal Actuarial Analyst | I29: 100702 | J29: Actuarial Assistant | K29: 2105 | L29: Life Office Management Assoc: Non-Executive Compensation Survey 04/01/2024 | M29: All Companies/All Companies/ | N29: USD | O29: 112.9 | P29: 123 | Q29: 131.2 | T29: 120.6 | U29: 132.2 | V29: 142.6 | W29: =IFERROR(VLOOKUP(I29, Summary!K:L, 2, FALSE), "") -> 123.31875 | X29: =IF(W29="","",W29/P29) -> 1.0025915 | Y29: =IFERROR(ROUND(VLOOKUP(I29, Summary!K:L, 2, FALSE)/VLOOKUP(I29, Summary!N:O, 2, FALSE), 1), "") -> 1 | Z29: =IFERROR(VLOOKUP(I29, Summary!Q:R, 2, FALSE), 0) -> 16 | AA29: 5-6 exams/ASA
A30: =I30 -> 100702 | B30: Actuarial | C30: Actuarial | D30: 45715 | E30: P2 | F30: =IFERROR(VLOOKUP(I30, 'Job Code Table'!D:E, 2, FALSE), "") -> Principal Actuarial Analyst | G30: =VLOOKUP(I30, '[1]Job Mapping'!$B:$N, 13, FALSE) -> Principal Actuarial Analyst | H30: =_xlfn.CONCAT(E30, "-", G30) -> P2-Principal Actuarial Analyst | I30: 100702 | J30: Actuarial - Life|Actuarial - Life Generalist/Multidiscipline|Intermediate (Professional)-P2-All Incumbent Global Grade | K30: FAD000-P2 | L30: Towers Watson: Financial Services MMPS 04/01/2024 | M30: Total Sample// | N30: USD | O30: 89.4 | P30: 97.4 | Q30: 109.8 | T30: 97.2 | U30: 108.1 | V30: 121.8 | W30: =IFERROR(VLOOKUP(I30, Summary!K:L, 2, FALSE), "") -> 123.31875 | X30: =IF(W30="","",W30/P30) -> 1.2661063 | Y30: =IFERROR(ROUND(VLOOKUP(I30, Summary!K:L, 2, FALSE)/VLOOKUP(I30, Summary!N:O, 2, FALSE), 1), "") -> 1 | Z30: =IFERROR(VLOOKUP(I30, Summary!Q:R, 2, FALSE), 0) -> 16 | AA30: 5-6 exams/ASA
A31: =I31 -> 100807 | B31: Actuarial | C31: Actuarial | D31: 45715 | E31: P2 | F31: =IFERROR(VLOOKUP(I31, 'Job Code Table'!D:E, 2, FALSE), "") -> Senior Actuarial Analyst | G31: =VLOOKUP(I31, '[1]Job Mapping'!$B:$N, 13, FALSE) -> Senior Actuarial Analyst | H31: =_xlfn.CONCAT(E31, "-", G31) -> P2-Senior Actuarial Analyst | I31: 100807 | J31: Level II - Actuarial Assistant | K31: 504 | L31: ClearSolutionsHR: Life/Health Actuarial Salary Survey 04/01/2024 | M31: Life & Health/all/ | N31: USD | O31: 93.5 | P31: 100.2 | Q31: 107.1 | T31: 99.9 | U31: 107.3 | V31: 114.8 | W31: =IFERROR(VLOOKUP(I31, Summary!K:L, 2, FALSE), "") -> 104.95357 | X31: =IF(W31="","",W31/P31) -> 1.0474408 | Y31: =IFERROR(ROUND(VLOOKUP(I31, Summary!K:L, 2, FALSE)/VLOOKUP(I31, Summary!N:O, 2, FALSE), 1), "") -> 1 | Z31: =IFERROR(VLOOKUP(I31, Summary!Q:R, 2, FALSE), 0) -> 28 | AA31: 3-5 exams
A32: =I32 -> 100807 | B32: Actuarial | C32: Actuarial | D32: 45715 | E32: P2 | F32: =IFERROR(VLOOKUP(I32, 'Job Code Table'!D:E, 2, FALSE), "") -> Senior Actuarial Analyst | G32: =VLOOKUP(I32, '[1]Job Mapping'!$B:$N, 13, FALSE) -> Senior Actuarial Analyst | H32: =_xlfn.CONCAT(E32, "-", G32) -> P2-Senior Actuarial Analyst | I32: 100807 | J32: Senior Actuarial Analyst | K32: 5032 | L32: Corporate Comp Strategies: Life Survey Group 03/01/2024 | M32: All// | N32: USD | O32: 97.8 | P32: 107.4 | Q32: 123.4 | T32: 105.5 | U32: 117.6 | V32: 135.1 | W32: =IFERROR(VLOOKUP(I32, Summary!K:L, 2, FALSE), "") -> 104.95357 | X32: =IF(W32="","",W32/P32) -> 0.97722134 | Y32: =IFERROR(ROUND(VLOOKUP(I32, Summary!K:L, 2, FALSE)/VLOOKUP(I32, Summary!N:O, 2, FALSE), 1), "") -> 1 | Z32: =IFERROR(VLOOKUP(I32, Summary!Q:R, 2, FALSE), 0) -> 28 | AA32: 3-5 exams
A33: =I33 -> 100807 | B33: Actuarial | C33: Actuarial | D33: 45715 | E33: P2 | F33: =IFERROR(VLOOKUP(I33, 'Job Code Table'!D:E, 2, FALSE), "") -> Senior Actuarial Analyst | G33: =VLOOKUP(I33, '[1]Job Mapping'!$B:$N, 13, FALSE) -> Senior Actuarial Analyst | H33: =_xlfn.CONCAT(E33, "-", G33) -> P2-Senior Actuarial Analyst | I33: 100807 | J33: Actuarial Assistant | K33: 2105 | L33: Life Office Management Assoc: Non-Executive Compensation Survey 04/01/2024 | M33: All Companies/All Companies/ | N33: USD | O33: 101.6 | P33: 110.7 | Q33: 118.1 | T33: 108.5 | U33: 119 | V33: 128.3 | W33: =IFERROR(VLOOKUP(I33, Summary!K:L, 2, FALSE), "") -> 104.95357 | X33: =IF(W33="","",W33/P33) -> 0.94809008 | Y33: =IFERROR(ROUND(VLOOKUP(I33, Summary!K:L, 2, FALSE)/VLOOKUP(I33, Summary!N:O, 2, FALSE), 1), "") -> 1 | Z33: =IFERROR(VLOOKUP(I33, Summary!Q:R, 2, FALSE), 0) -> 28 | AA33: 3-5 exams
A34: =I34 -> 100807 | B34: Actuarial | C34: Actuarial | D34: 45715 | E34: P2 | F34: =IFERROR(VLOOKUP(I34, 'Job Code Table'!D:E, 2, FALSE), "") -> Senior Actuarial Analyst | G34: =VLOOKUP(I34, '[1]Job Mapping'!$B:$N, 13, FALSE) -> Senior Actuarial Analyst | H34: =_xlfn.CONCAT(E34, "-", G34) -> P2-Senior Actuarial Analyst | I34: 100807 | J34: Actuarial - Life|Actuarial - Life Generalist/Multidiscipline|Intermediate (Professional)-P2-All Incumbent Global Grade | K34: FAD000-P2 | L34: Towers Watson: Financial Services MMPS 04/01/2024 | M34: Total Sample// | N34: USD | O34: 89.4 | P34: 97.4 | Q34: 109.8 | T34: 97.2 | U34: 108.1 | V34: 121.8 | W34: =IFERROR(VLOOKUP(I34, Summary!K:L, 2, FALSE), "") -> 104.95357 | X34: =IF(W34="","",W34/P34) -> 1.0775521 | Y34: =IFERROR(ROUND(VLOOKUP(I34, Summary!K:L, 2, FALSE)/VLOOKUP(I34, Summary!N:O, 2, FALSE), 1), "") -> 1 | Z34: =IFERROR(VLOOKUP(I34, Summary!Q:R, 2, FALSE), 0) -> 28 | AA34: 3-5 exams
... A45: =I45 -> 100025 | B45: Actuarial | C45: Actuarial | D45: 45715 | E45: P5 | F45: =IFERROR(VLOOKUP(I45, 'Job Code Table'!D:E, 2, FALSE), "") -> Actuary | G45: =VLOOKUP(I45, '[1]Job Mapping'!$B:$N, 13, FALSE) -> Actuary | H45: =_xlfn.CONCAT(E45, "-", G45) -> P5-Actuary | I45: 100025 | J45: Actuarial - Life|Actuarial - Life Generalist/Multidiscipline|Expert (Professional)-P5-All Incumbent Global Grade | K45: FAD000-P5 | L45: Towers Watson: Financial Services MMPS 04/01/2024 | M45: Total Sample// | N45: USD | O45: 141.4 | P45: 184.1 | Q45: 200.2 | T45: 165.8 | U45: 226.6 | V45: 251.2 | W45: =IFERROR(VLOOKUP(I45, Summary!K:L, 2, FALSE), "") -> 185.225 | X45: =IF(W45="","",W45/P45) -> 1.0061108 | Y45: =IFERROR(ROUND(VLOOKUP(I45, Summary!K:L, 2, FALSE)/VLOOKUP(I45, Summary!N:O, 2, FALSE), 1), "") -> 1.1 | Z45: =IFERROR(VLOOKUP(I45, Summary!Q:R, 2, FALSE), 0) -> 8 | AA45: FSA, 6-10 years experience
A46: =I46 -> 100808 | B46: Actuarial | C46: Actuarial | D46: 45715 | E46: P5 | F46: =IFERROR(VLOOKUP(I46, 'Job Code Table'!D:E, 2, FALSE), "") -> Senior Actuary | G46: =VLOOKUP(I46, '[1]Job Mapping'!$B:$N, 13, FALSE) -> Senior Actuary | H46: =_xlfn.CONCAT(E46, "-", G46) -> P5-Senior Actuary | I46: 100808 | J46: Senior Actuary | K46: 5022 | L46: Corporate Comp Strategies: Life Survey Group 03/01/2024 | M46: All// | N46: USD | O46: 175.2 | P46: 187.6 | Q46: 208.7 | T46: 213.1 | U46: 231.5 | V46: 265 | W46: =IFERROR(VLOOKUP(I46, Summary!K:L, 2, FALSE), "") -> 210 | X46: =IF(W46="","",W46/P46) -> 1.119403 | Y46: =IFERROR(ROUND(VLOOKUP(I46, Summary!K:L, 2, FALSE)/VLOOKUP(I46, Summary!N:O, 2, FALSE), 1), "") -> 1.1 | Z46: =IFERROR(VLOOKUP(I46, Summary!Q:R, 2, FALSE), 0) -> 1
A47: =I47 -> 100808 | B47: Actuarial | C47: Actuarial | D47: 45715 | E47: P5 | F47: =IFERROR(VLOOKUP(I47, 'Job Code Table'!D:E, 2, FALSE), "") -> Senior Actuary | G47: =VLOOKUP(I47, '[1]Job Mapping'!$B:$N, 13, FALSE) -> Senior Actuary | H47: =_xlfn.CONCAT(E47, "-", G47) -> P5-Senior Actuary | I47: 100808 | J47: Actuary | K47: 2102 | L47: Life Office Management Assoc: Non-Executive Compensation Survey 04/01/2024 | M47: All Companies/All Companies/ | N47: USD | O47: 187.7 | P47: 201.4 | Q47: 221.3 | T47: 225.4 | U47: 246.8 | V47: 274 | W47: =IFERROR(VLOOKUP(I47, Summary!K:L, 2, FALSE), "") -> 210 | X47: =IF(W47="","",W47/P47) -> 1.0427011 | Y47: =IFERROR(ROUND(VLOOKUP(I47, Summary!K:L, 2, FALSE)/VLOOKUP(I47, Summary!N:O, 2, FALSE), 1), "") -> 1.1 | Z47: =IFERROR(VLOOKUP(I47, Summary!Q:R, 2, FALSE), 0) -> 1
A48: =I48 -> 100808 | B48: Actuarial | C48: Actuarial | D48: 45715 | E48: P5 | F48: =IFERROR(VLOOKUP(I48, 'Job Code Table'!D:E, 2, FALSE), "") -> Senior Actuary | G48: =VLOOKUP(I48, '[1]Job Mapping'!$B:$N, 13, FALSE) -> Senior Actuary | H48: =_xlfn.CONCAT(E48, "-", G48) -> P5-Senior Actuary | I48: 100808 | J48: Actuarial - Life|Actuarial - Life Generalist/Multidiscipline|Expert (Professional)-P5-All Incumbent Global Grade | K48: FAD000-P5 | L48: Towers Watson: Financial Services MMPS 04/01/2024 | M48: Total Sample// | N48: USD | O48: 141.4 | P48: 184.1 | Q48: 200.2 | T48: 165.8 | U48: 226.6 | V48: 251.2 | W48: =IFERROR(VLOOKUP(I48, Summary!K:L, 2, FALSE), "") -> 210 | X48: =IF(W48="","",W48/P48) -> 1.1406844 | Y48: =IFERROR(ROUND(VLOOKUP(I48, Summary!K:L, 2, FALSE)/VLOOKUP(I48, Summary!N:O, 2, FALSE), 1), "") -> 1.1 | Z48: =IFERROR(VLOOKUP(I48, Summary!Q:R, 2, FALSE), 0) -> 1
A49: =I49 -> 100137 | B49: Audit | C49: Audit | D49: 45670 | E49: M3 | F49: =IFERROR(VLOOKUP(I49, 'Job Code Table'!D:E, 2, FALSE), "") -> Audit Director | G49: =VLOOKUP(I49, '[1]Job Mapping'!$B:$N, 13, FALSE) -> Director Audit | H49: =_xlfn.CONCAT(E49, "-", G49) -> M3-Director Audit | I49: 100137 | J49: Internal Audit - Senior Manager (M4) | K49: LCA.05.000.M40 | L49: Mercer: MBD - Information Technology Report 03/01/2021 | M49: All Data// | N49: USD | O49: 150.4 | P49: 175.5 | Q49: 207.3 | T49: 150.6 | U49: 197.6 | V49: 240 | W49: =IFERROR(VLOOKUP(I49, Summary!K:L, 2, FALSE), "") -> 157.6 | X49: =IF(W49="","",W49/P49) -> 0.8980057 | Y49: =IFERROR(ROUND(VLOOKUP(I49, Summary!K:L, 2, FALSE)/VLOOKUP(I49, Summary!N:O, 2, FALSE), 1), "") -> 0.8 | Z49: =IFERROR(VLOOKUP(I49, Summary!Q:R, 2, FALSE), 0) -> 3
A50: =I50 -> 100137 | B50: Audit | C50: Audit | D50: 45670 | E50: M3 | F50: =IFERROR(VLOOKUP(I50, 'Job Code Table'!D:E, 2, FALSE), "") -> Audit Director | G50: =VLOOKUP(I50, '[1]Job Mapping'!$B:$N, 13, FALSE) -> Director Audit | H50: =_xlfn.CONCAT(E50, "-", G50) -> M3-Director Audit | I50: 100137 | J50: Audit Director | K50: 2485 | L50: Peer - Global Network | M50: Exchange Job: Audit Director; Exchange: Global Network; Countries: USA; | N50: USD | O50: 165.6 | P50: 188.3 | Q50: 214.3 | T50: 193.1 | U50: 224.5 | V50: 259.1 | W50: =IFERROR(VLOOKUP(I50, Summary!K:L, 2, FALSE), "") -> 157.6 | X50: =IF(W50="","",W50/P50) -> 0.83696229 | Y50: =IFERROR(ROUND(VLOOKUP(I50, Summary!K:L, 2, FALSE)/VLOOKUP(I50, Summary!N:O, 2, FALSE), 1), "") -> 0.8 | Z50: =IFERROR(VLOOKUP(I50, Summary!Q:R, 2, FALSE), 0) -> 3
...

Sheet Employees
A1: Job Title | B1: Job Code | C1: Pay Market | D1: Name | E1: Employee ID | F1: MRP | G1: Job Base Rate | H1: Employee Annual Rate | I1: MRP | J1: TCC Amt | K1: % | L1: Source | M1: Comment | N1: Job Family | O1: Job Level | P1: WTW Benchmark | Q1: Chart
A2: Actuarial Analyst | B2: 100024 | C2: National | D2: Chloe Argue | E2: 10133710 | F2: National | G2: 88.4 | H2: 85 | I2: 96.2 | J2: 93.3 | K2: 85 | L2: 91.1 | N2: =VLOOKUP(B2,'New Matches'!A:B,2,FALSE) -> Actuarial | O2: =VLOOKUP(B2, 'New Matches'!A:I, 5, FALSE) -> P1 | P2: =IFERROR(VLOOKUP(O2, Summary!T:U, 2, FALSE), "") -> 0.13 | Q2: =IFERROR(VLOOKUP(Employees!O2, Summary!T:V, 3, FALSE), "") -> Professional
A3: Actuarial Analyst | B3: 100024 | C3: National | D3: Daniel Bell | E3: 10135617 | F3: National | G3: 88.4 | H3: 90 | I3: 101.8 | J3: 93.3 | K3: 90 | L3: 96.5 | N3: =VLOOKUP(B3,'New Matches'!A:B,2,FALSE) -> Actuarial | O3: =VLOOKUP(B3, 'New Matches'!A:I, 5, FALSE) -> P1 | P3: =IFERROR(VLOOKUP(O3, Summary!T:U, 2, FALSE), "") -> 0.13 | Q3: =IFERROR(VLOOKUP(Employees!O3, Summary!T:V, 3, FALSE), "") -> Professional
A4: Actuarial Analyst | B4: 100024 | C4: National | D4: Peter Brady | E4: 10133478 | F4: National | G4: 88.4 | H4: 89.5 | I4: 101.2 | J4: 93.3 | K4: 89.5 | L4: 95.9 | N4: =VLOOKUP(B4,'New Matches'!A:B,2,FALSE) -> Actuarial | O4: =VLOOKUP(B4, 'New Matches'!A:I, 5, FALSE) -> P1 | P4: =IFERROR(VLOOKUP(O4, Summary!T:U, 2, FALSE), "") -> 0.13 | Q4: =IFERROR(VLOOKUP(Employees!O4, Summary!T:V, 3, FALSE), "") -> Professional
A5: Actuarial Analyst | B5: 100024 | C5: National | D5: Zander Felde | E5: 10131626 | F5: National | G5: 88.4 | H5: 95 | I5: 107.5 | J5: 93.3 | K5: 95 | L5: 101.8 | N5: =VLOOKUP(B5,'New Matches'!A:B,2,FALSE) -> Actuarial | O5: =VLOOKUP(B5, 'New Matches'!A:I, 5, FALSE) -> P1 | P5: =IFERROR(VLOOKUP(O5, Summary!T:U, 2, FALSE), "") -> 0.13 | Q5: =IFERROR(VLOOKUP(Employees!O5, Summary!T:V, 3, FALSE), "") -> Professional
A6: Actuarial Analyst | B6: 100024 | C6: National | D6: Kevin Fernandez | E6: 10135195 | F6: National | G6: 88.4 | H6: 81.5 | I6: 92.2 | J6: 93.3 | K6: 81.5 | L6: 87.4 | N6: =VLOOKUP(B6,'New Matches'!A:B,2,FALSE) -> Actuarial | O6: =VLOOKUP(B6, 'New Matches'!A:I, 5, FALSE) -> P1 | P6: =IFERROR(VLOOKUP(O6, Summary!T:U, 2, FALSE), "") -> 0.13 | Q6: =IFERROR(VLOOKUP(Employees!O6, Summary!T:V, 3, FALSE), "") -> Professional
A7: Actuarial Analyst | B7: 100024 | C7: National | D7: Andrew Johnson | E7: 10133706 | F7: National | G7: 88.4 | H7: 91.5 | I7: 103.5 | J7: 93.3 | K7: 91.5 | L7: 98.1 | N7: =VLOOKUP(B7,'New Matches'!A:B,2,FALSE) -> Actuarial | O7: =VLOOKUP(B7, 'New Matches'!A:I, 5, FALSE) -> P1 | P7: =IFERROR(VLOOKUP(O7, Summary!T:U, 2, FALSE), "") -> 0.13 | Q7: =IFERROR(VLOOKUP(Employees!O7, Summary!T:V, 3, FALSE), "") -> Professional
A8: Actuarial Analyst | B8: 100024 | C8: National | D8: Nick Kirchner | E8: 10135213 | F8: National | G8: 88.4 | H8: 100 | I8: 113.1 | J8: 93.3 | K8: 100 | L8: 107.2 | N8: =VLOOKUP(B8,'New Matches'!A:B,2,FALSE) -> Actuarial | O8: =VLOOKUP(B8, 'New Matches'!A:I, 5, FALSE) -> P1 | P8: =IFERROR(VLOOKUP(O8, Summary!T:U, 2, FALSE), "") -> 0.13 | Q8: =IFERROR(VLOOKUP(Employees!O8, Summary!T:V, 3, FALSE), "") -> Professional
A9: Actuarial Analyst | B9: 100024 | C9: National | D9: Aron Ma | E9: 10135027 | F9: National | G9: 88.4 | H9: 92.5 | I9: 104.6 | J9: 93.3 | K9: 92.5 | L9: 99.1 | N9: =VLOOKUP(B9,'New Matches'!A:B,2,FALSE) -> Actuarial | O9: =VLOOKUP(B9, 'New Matches'!A:I, 5, FALSE) -> P1 | P9: =IFERROR(VLOOKUP(O9, Summary!T:U, 2, FALSE), "") -> 0.13 | Q9: =IFERROR(VLOOKUP(Employees!O9, Summary!T:V, 3, FALSE), "") -> Professional
A10: Actuarial Analyst | B10: 100024 | C10: National | D10: Katelyn Mamrick | E10: 10133719 | F10: National | G10: 88.4 | H10: 100.5 | I10: 113.7 | J10: 93.3 | K10: 100.5 | L10: 107.7 | N10: =VLOOKUP(B10,'New Matches'!A:B,2,FALSE) -> Actuarial | O10: =VLOOKUP(B10, 'New Matches'!A:I, 5, FALSE) -> P1 | P10: =IFERROR(VLOOKUP(O10, Summary!T:U, 2, FALSE), "") -> 0.13 | Q10: =IFERROR(VLOOKUP(Employees!O10, Summary!T:V, 3, FALSE), "") -> Professional
A11: Actuarial Analyst | B11: 100024 | C11: National | D11: Heidi Marg | E11: 10133713 | F11: National | G11: 88.4 | H11: 94.5 | I11: 106.9 | J11: 93.3 | K11: 94.5 | L11: 101.3 | N11: =VLOOKUP(B11,'New Matches'!A:B,2,FALSE) -> Actuarial | O11: =VLOOKUP(B11, 'New Matches'!A:I, 5, FALSE) -> P1 | P11: =IFERROR(VLOOKUP(O11, Summary!T:U, 2, FALSE), "") -> 0.13 | Q11: =IFERROR(VLOOKUP(Employees!O11, Summary!T:V, 3, FALSE), "") -> Professional
A12: Actuarial Analyst | B12: 100024 | C12: National | D12: Hannah Moses | E12: 10135747 | F12: National | G12: 88.4 | H12: 82.5 | I12: 93.3 | J12: 93.3 | K12: 82.5 | L12: 88.4 | N12: =VLOOKUP(B12,'New Matches'!A:B,2,FALSE) -> Actuarial | O12: =VLOOKUP(B12, 'New Matches'!A:I, 5, FALSE) -> P1 | P12: =IFERROR(VLOOKUP(O12, Summary!T:U, 2, FALSE), "") -> 0.13 | Q12: =IFERROR(VLOOKUP(Employees!O12, Summary!T:V, 3, FALSE), "") -> Professional
A13: Actuarial Analyst | B13: 100024 | C13: National | D13: Jordy Pauly | E13: 10135054 | F13: National | G13: 88.4 | H13: 90.5 | I13: 102.4 | J13: 93.3 | K13: 90.5 | L13: 97 | N13: =VLOOKUP(B13,'New Matches'!A:B,2,FALSE) -> Actuarial | O13: =VLOOKUP(B13, 'New Matches'!A:I, 5, FALSE) -> P1 | P13: =IFERROR(VLOOKUP(O13, Summary!T:U, 2, FALSE), "") -> 0.13 | Q13: =IFERROR(VLOOKUP(Employees!O13, Summary!T:V, 3, FALSE), "") -> Professional
... A96: Audit Director | B96: 100137 | C96: National | D96: David Johnson | E96: 10132089 | F96: National | G96: 187 | H96: 163.8 | I96: 87.6 | J96: 216.2 | K96: 163.8 | L96: 75.8 | N96: =VLOOKUP(B96,'New Matches'!A:B,2,FALSE) -> Audit | O96: =VLOOKUP(B96, 'New Matches'!A:I, 5, FALSE) -> M3 | P96: =IFERROR(VLOOKUP(O96, Summary!T:U, 2, FALSE), "") -> 0.31 | Q96: =IFERROR(VLOOKUP(Employees!O96, Summary!T:V, 3, FALSE), "") -> Management
A97: Audit Director | B97: 100137 | C97: National | D97: Lynn Johnson | E97: 10100256 | F97: National | G97: 187 | H97: 140 | I97: 74.9 | J97: 216.2 | K97: 140 | L97: 64.8 | M97: Evaluate if employee is leveled correctly based on market data | N97: =VLOOKUP(B97,'New Matches'!A:B,2,FALSE) -> Audit | O97: =VLOOKUP(B97, 'New Matches'!A:I, 5, FALSE) -> M3 | P97: =IFERROR(VLOOKUP(O97, Summary!T:U, 2, FALSE), "") -> 0.31 | Q97: =IFERROR(VLOOKUP(Employees!O97, Summary!T:V, 3, FALSE), "") -> Management
A98: Audit Analyst Senior | B98: 100136 | C98: National | D98: Mallory Meidl | E98: 10131271 | F98: National | G98: 101.3 | H98: 99.3 | I98: 98 | J98: 106.2 | K98: 99.3 | L98: 93.5 | N98: =VLOOKUP(B98,'New Matches'!A:B,2,FALSE) -> Audit | O98: =VLOOKUP(B98, 'New Matches'!A:I, 5, FALSE) -> P3 | P98: =IFERROR(VLOOKUP(O98, Summary!T:U, 2, FALSE), "") -> 0.33 | Q98: =IFERROR(VLOOKUP(Employees!O98, Summary!T:V, 3, FALSE), "") -> Professional
A99: Audit Analyst Senior | B99: 100136 | C99: National | D99: Tasha Scovill | E99: 10102174 | F99: National | G99: 101.3 | H99: 69.6 | I99: 68.7 | J99: 106.2 | K99: 69.6 | L99: 65.5 | M99: Evaluate if employee is leveled correctly based on market data | N99: =VLOOKUP(B99,'New Matches'!A:B,2,FALSE) -> Audit | O99: =VLOOKUP(B99, 'New Matches'!A:I, 5, FALSE) -> P3 | P99: =IFERROR(VLOOKUP(O99, Summary!T:U, 2, FALSE), "") -> 0.33 | Q99: =IFERROR(VLOOKUP(Employees!O99, Summary!T:V, 3, FALSE), "") -> Professional
A100: Audit Principal | B100: 100138 | C100: National | D100: Claire Chhettri | E100: 10135959 | F100: National | G100: 127.1 | H100: 118 | I100: 92.8 | J100: 138.7 | K100: 118 | L100: 85.1 | N100: =VLOOKUP(B100,'New Matches'!A:B,2,FALSE) -> Audit | O100: =VLOOKUP(B100, 'New Matches'!A:I, 5, FALSE) -> P4 | P100: =IFERROR(VLOOKUP(O100, Summary!T:U, 2, FALSE), "") -> 0.21 | Q100: =IFERROR(VLOOKUP(Employees!O100, Summary!T:V, 3, FALSE), "") -> Professional
A101: Audit Principal | B101: 100138 | C101: National | D101: Brett Goda | E101: 10136111 | F101: National | G101: 127.1 | H101: 105 | I101: 82.6 | J101: 138.7 | K101: 105 | L101: 75.7 | N101: =VLOOKUP(B101,'New Matches'!A:B,2,FALSE) -> Audit | O101: =VLOOKUP(B101, 'New Matches'!A:I, 5, FALSE) -> P4 | P101: =IFERROR(VLOOKUP(O101, Summary!T:U, 2, FALSE), "") -> 0.21 | Q101: =IFERROR(VLOOKUP(Employees!O101, Summary!T:V, 3, FALSE), "") -> Professional
A102: Audit Principal | B102: 100138 | C102: National | D102: Daniel Ludowese | E102: 10132219 | F102: National | G102: 127.1 | H102: 119 | I102: 93.6 | J102: 138.7 | K102: 119 | L102: 85.8 | N102: =VLOOKUP(B102,'New Matches'!A:B,2,FALSE) -> Audit | O102: =VLOOKUP(B102, 'New Matches'!A:I, 5, FALSE) -> P4 | P102: =IFERROR(VLOOKUP(O102, Summary!T:U, 2, FALSE), "") -> 0.21 | Q102: =IFERROR(VLOOKUP(Employees!O102, Summary!T:V, 3, FALSE), "") -> Professional
A103: Audit Principal | B103: 100138 | C103: National | D103: Lisa Manders | E103: 10101452 | F103: National | G103: 127.1 | H103: 89.3 | I103: 70.3 | J103: 138.7 | K103: 89.3 | L103: 64.4 | M103: Evaluate if employee is leveled correctly based on market data | N103: =VLOOKUP(B103,'New Matches'!A:B,2,FALSE) -> Audit | O103: =VLOOKUP(B103, 'New Matches'!A:I, 5, FALSE) -> P4 | P103: =IFERROR(VLOOKUP(O103, Summary!T:U, 2, FALSE), "") -> 0.21 | Q103: =IFERROR(VLOOKUP(Employees!O103, Summary!T:V, 3, FALSE), "") -> Professional
A104: Audit Principal | B104: 100138 | C104: National | D104: Emma Onyancha | E104: 10134558 | F104: National | G104: 127.1 | H104: 110 | I104: 86.5 | J104: 138.7 | K104: 110 | L104: 79.3 | N104: =VLOOKUP(B104,'New Matches'!A:B,2,FALSE) -> Audit | O104: =VLOOKUP(B104, 'New Matches'!A:I, 5, FALSE) -> P4 | P104: =IFERROR(VLOOKUP(O104, Summary!T:U, 2, FALSE), "") -> 0.21 | Q104: =IFERROR(VLOOKUP(Employees!O104, Summary!T:V, 3, FALSE), "") -> Professional
A105: Audit Principal | B105: 100138 | C105: National | D105: Katelynn Robinson | E105: 10101304 | F105: National | G105: 127.1 | H105: 97.6 | I105: 76.8 | J105: 138.7 | K105: 97.6 | L105: 70.4 | N105: =VLOOKUP(B105,'New Matches'!A:B,2,FALSE) -> Audit | O105: =VLOOKUP(B105, 'New Matches'!A:I, 5, FALSE) -> P4 | P105: =IFERROR(VLOOKUP(O105, Summary!T:U, 2, FALSE), "") -> 0.21 | Q105: =IFERROR(VLOOKUP(Employees!O105, Summary!T:V, 3, FALSE), "") -> Professional
A106: Audit Principal | B106: 100138 | C106: National | D106: Sarah Schwarzkopf | E106: 10134891 | F106: National | G106: 127.1 | H106: 98 | I106: 77.1 | J106: 138.7 | K106: 98 | L106: 70.7 | N106: =VLOOKUP(B106,'New Matches'!A:B,2,FALSE) -> Audit | O106: =VLOOKUP(B106, 'New Matches'!A:I, 5, FALSE) -> P4 | P106: =IFERROR(VLOOKUP(O106, Summary!T:U, 2, FALSE), "") -> 0.21 | Q106: =IFERROR(VLOOKUP(Employees!O106, Summary!T:V, 3, FALSE), "") -> Professional
A107: Audit Principal | B107: 100138 | C107: National | D107: Colette Tupy | E107: 10132290 | F107: National | G107: 127.1 | H107: 117.8 | I107: 92.7 | J107: 138.7 | K107: 117.8 | L107: 84.9 | N107: =VLOOKUP(B107,'New Matches'!A:B,2,FALSE) -> Audit | O107: =VLOOKUP(B107, 'New Matches'!A:I, 5, FALSE) -> P4 | P107: =IFERROR(VLOOKUP(O107, Summary!T:U, 2, FALSE), "") -> 0.21 | Q107: =IFERROR(VLOOKUP(Employees!O107, Summary!T:V, 3, FALSE), "") -> Professional
A108: Audit Program Manager | B108: 100140 | C108: National | D108: Lisa Clemens | E108: 10100266 | F108: National | G108: 130.5 | H108: 130.7 | I108: 100.2 | J108: 141.7 | K108: 130.7 | L108: 92.2 | N108: =VLOOKUP(B108,'New Matches'!A:B,2,FALSE) -> Audit | O108: =VLOOKUP(B108, 'New Matches'!A:I, 5, FALSE) -> P4 | P108: =IFERROR(VLOOKUP(O108, Summary!T:U, 2, FALSE), "") -> 0.21 | Q108: =IFERROR(VLOOKUP(Employees!O108, Summary!T:V, 3, FALSE), "") -> Professional
A109: Audit Program Manager | B109: 100140 | C109: National | D109: Mathias Int-Veen | E109: 15001913 | F109: National | G109: 130.5 | H109: 147.1 | I109: 112.7 | J109: 141.7 | K109: 147.1 | L109: 103.8 | N109: =VLOOKUP(B109,'New Matches'!A:B,2,FALSE) -> Audit | O109: =VLOOKUP(B109, 'New Matches'!A:I, 5, FALSE) -> P4 | P109: =IFERROR(VLOOKUP(O109, Summary!T:U, 2, FALSE), "") -> 0.21 | Q109: =IFERROR(VLOOKUP(Employees!O109, Summary!T:V, 3, FALSE), "") -> Professional
A110: Audit Program Manager | B110: 100140 | C110: National | D110: Michael Ritchie | E110: 10136009 | F110: National | G110: 130.5 | H110: 145 | I110: 111.1 | J110: 141.7 | K110: 145 | L110: 102.3 | N110: =VLOOKUP(B110,'New Matches'!A:B,2,FALSE) -> Audit | O110: =VLOOKUP(B110, 'New Matches'!A:I, 5, FALSE) -> P4 | P110: =IFERROR(VLOOKUP(O110, Summary!T:U, 2, FALSE), "") -> 0.21 | Q110: =IFERROR(VLOOKUP(Employees!O110, Summary!T:V, 3, FALSE), "") -> Professional
A111: Manager Data & Analytics | B111: 101342 | C111: National | D111: Arin Arpinar | E111: 10134236 | F111: National | G111: 145 | H111: 130 | I111: 89.7 | J111: 159.6 | K111: 130 | L111: 81.5 | N111: =VLOOKUP(B111,'New Matches'!A:B,2,FALSE) -> Data Analytics | O111: =VLOOKUP(B111, 'New Matches'!A:I, 5, FALSE) -> M2 | P111: =IFERROR(VLOOKUP(O111, Summary!T:U, 2, FALSE), "") -> 0.38 | Q111: =IFERROR(VLOOKUP(Employees!O111, Summary!T:V, 3, FALSE), "") -> Management
A112: Manager Data & Analytics | B112: 101342 | C112: National | D112: Lisa Tomasko | E112: 10100350 | F112: National | G112: 145 | H112: 155 | I112: 106.9 | J112: 159.6 | K112: 155 | L112: 97.1 | N112: =VLOOKUP(B112,'New Matches'!A:B,2,FALSE) -> Data Analytics | O112: =VLOOKUP(B112, 'New Matches'!A:I, 5, FALSE) -> M2 | P112: =IFERROR(VLOOKUP(O112, Summary!T:U, 2, FALSE), "") -> 0.38 | Q112: =IFERROR(VLOOKUP(Employees!O112, Summary!T:V, 3, FALSE), "") -> Management
A113: Manager Data Engineering | B113: 101637 | C113: National | D113: Oscar Kalipe | E113: 10134328 | F113: National | G113: 163.9 | H113: 150 | I113: 91.5 | J113: 177.1 | K113: 150 | L113: 84.7 | N113: =VLOOKUP(B113,'New Matches'!A:B,2,FALSE) -> Data Analytics | O113: =VLOOKUP(B113, 'New Matches'!A:I, 5, FALSE) -> M2 | P113: =IFERROR(VLOOKUP(O113, Summary!T:U, 2, FALSE), "") -> 0.38 | Q113: =IFERROR(VLOOKUP(Employees!O113, Summary!T:V, 3, FALSE), "") -> Management
A114: Data Science Director | B114: 100349 | C114: National | D114: Monica King | E114: 10130224 | F114: National | G114: 216.1 | H114: 195.8 | I114: 90.6 | J114: 255.3 | K114: 195.8 | L114: 76.7 | N114: =VLOOKUP(B114,'New Matches'!A:B,2,FALSE) -> Data Analytics | O114: =VLOOKUP(B114, 'New Matches'!A:I, 5, FALSE) -> M3 | P114: =IFERROR(VLOOKUP(O114, Summary!T:U, 2, FALSE), "") -> 0.31 | Q114: =IFERROR(VLOOKUP(Employees!O114, Summary!T:V, 3, FALSE), "") -> Management
A115: Director Data & Analytics | B115: 100665 | C115: National | D115: Kristine Arneson | E115: 10134798 | F115: National | G115: 199.6 | H115: 165 | I115: 82.7 | J115: 230.6 | K115: 165 | L115: 71.6 | N115: =VLOOKUP(B115,'New Matches'!A:B,2,FALSE) -> Data Analytics | O115: =VLOOKUP(B115, 'New Matches'!A:I, 5, FALSE) -> M3 | P115: =IFERROR(VLOOKUP(O115, Summary!T:U, 2, FALSE), "") -> 0.31 | Q115: =IFERROR(VLOOKUP(Employees!O115, Summary!T:V, 3, FALSE), "") -> Management
... A117: Director Data & Analytics | B117: 100665 | C117: National | D117: Andrew Morem | E117: 10101225 | F117: National | G117: 199.6 | H117: 155.6 | I117: 78 | J117: 230.6 | K117: 155.6 | L117: 67.5 | N117: =VLOOKUP(B117,'New Matches'!A:B,2,FALSE) -> Data Analytics | O117: =VLOOKUP(B117, 'New Matches'!A:I, 5, FALSE) -> M3 | P117: =IFERROR(VLOOKUP(O117, Summary!T:U, 2, FALSE), "") -> 0.31 | Q117: =IFERROR(VLOOKUP(Employees!O117, Summary!T:V, 3, FALSE), "") -> Management
A118: Senior Director Data & Analytics | B118: 101643 | C118: National | D118: Natalie Johnson | E118: 10100840 | F118: National | G118: 229.1 | H118: 170 | I118: 74.2 | J118: 276.1 | K118: 170 | L118: 61.6 | M118: Evaluate if employee is leveled correctly based on market data | N118: =VLOOKUP(B118,'New Matches'!A:B,2,FALSE) -> Data Analytics | O118: =VLOOKUP(B118, 'New Matches'!A:I, 5, FALSE) -> M4 | P118: =IFERROR(VLOOKUP(O118, Summary!T:U, 2, FALSE), "") -> 0.18 | Q118: =IFERROR(VLOOKUP(Employees!O118, Summary!T:V, 3, FALSE), "") -> Management
A119: Senior Director Data & Analytics | B119: 101643 | C119: National | D119: Tyler Mittelstadt | E119: 10131505 | F119: National | G119: 229.1 | H119: 216.7 | I119: 94.6 | J119: 276.1 | K119: 216.7 | L119: 78.5 | N119: =VLOOKUP(B119,'New Matches'!A:B,2,FALSE) -> Data Analytics | O119: =VLOOKUP(B119, 'New Matches'!A:I, 5, FALSE) -> M4 | P119: =IFERROR(VLOOKUP(O119, Summary!T:U, 2, FALSE), "") -> 0.18 | Q119: =IFERROR(VLOOKUP(Employees!O119, Summary!T:V, 3, FALSE), "") -> Management
A120: Analytics Consultant | B120: 101566 | C120: National | D120: Phil Johnson | E120: 10131662 | F120: National | G120: 86.2 | H120: 67 | I120: 77.7 | J120: 89.4 | K120: 67 | L120: 74.9 | N120: =VLOOKUP(B120,'New Matches'!A:B,2,FALSE) -> Data Analytics | O120: =VLOOKUP(B120, 'New Matches'!A:I, 5, FALSE) -> P2 | P120: =IFERROR(VLOOKUP(O120, Summary!T:U, 2, FALSE), "") -> 0.25 | Q120: =IFERROR(VLOOKUP(Employees!O120, Summary!T:V, 3, FALSE), "") -> Professional
A121: Analytics Consultant | B121: 101566 | C121: National | D121: Adam Schulz | E121: 10134153 | F121: National | G121: 86.2 | H121: 77.3 | I121: 89.7 | J121: 89.4 | K121: 77.3 | L121: 86.5 | N121: =VLOOKUP(B121,'New Matches'!A:B,2,FALSE) -> Data Analytics | O121: =VLOOKUP(B121, 'New Matches'!A:I, 5, FALSE) -> P2 | P121: =IFERROR(VLOOKUP(O121, Summary!T:U, 2, FALSE), "") -> 0.25 | Q121: =IFERROR(VLOOKUP(Employees!O121, Summary!T:V, 3, FALSE), "") -> Professional
A122: Data Scientist | B122: 100298 | C122: National | D122: Marissa Munley | E122: 10130434 | F122: National | G122: 124.6 | H122: 97.6 | I122: 78.3 | J122: 130.3 | K122: 97.6 | L122: 74.9 | N122: =VLOOKUP(B122,'New Matches'!A:B,2,FALSE) -> Data Analytics | O122: =VLOOKUP(B122, 'New Matches'!A:I, 5, FALSE) -> P2 | P122: =IFERROR(VLOOKUP(O122, Summary!T:U, 2, FALSE), "") -> 0.25 | Q122: =IFERROR(VLOOKUP(Employees!O122, Summary!T:V, 3, FALSE), "") -> Professional
A123: Data Scientist | B123: 100298 | C123: National | D123: Linh Nguyen | E123: 10133728 | F123: National | G123: 124.6 | H123: 120 | I123: 96.3 | J123: 130.3 | K123: 120 | L123: 92.1 | N123: =VLOOKUP(B123,'New Matches'!A:B,2,FALSE) -> Data Analytics | O123: =VLOOKUP(B123, 'New Matches'!A:I, 5, FALSE) -> P2 | P123: =IFERROR(VLOOKUP(O123, Summary!T:U, 2, FALSE), "") -> 0.25 | Q123: =IFERROR(VLOOKUP(Employees!O123, Summary!T:V, 3, FALSE), "") -> Professional
...

Sheet Summary
K1: Avg Employee Pay | N1: Avg Market Rate | Q1: Incumbent Count
A2: Job Family | B2: Information Technology | K2: Row Labels | L2: Average of Employee Annual Rate | N2: Row Labels | O2: Average of Base 50th | Q2: Row Labels | R2: Count of Employee ID | T2: Chart Guidelines
K3: 100002 | L3: 73.5 | N3: 100135 | O3: 67.75 | Q3: 100002 | R3: 1 | T3: Level | U3: WTW Guidelines | V3: Chart
A4: Row Labels | B4: Count of Job Code | C4: Min of Base 50th2 | D4: Average of Base 50th | E4: Max of Base 50th2 | F4: Spread - Below | G4: Spread - Above | H4: Level Progression | K4: 100003 | L4: 102.9375 | N4: 100136 | O4: 101.25 | Q4: 100003 | R4: 8 | T4: P1 | U4: 0.13 | V4: Professional
A5: Business Systems Analysis | K5: 100004 | L5: 195.7 | N5: 100137 | O5: 186.95 | Q5: 100004 | R5: 1 | T5: P2 | U5: 0.25 | V5: Professional
A6: M2-Senior Manager Business Systems Analysis | B6: 3 | C6: 138.5 | D6: 145.6 | E6: 152.5 | F6: =IFERROR((C6-D6)/C6, "") -> -0.051263538 | G6: =IFERROR((D6-E6)/D6, "") -> -0.04739011 | H6: =(D6-D5)/D5 -> #DIV/0! | K6: 100005 | L6: 133.56 | N6: 100138 | O6: 127.125 | Q6: 100005 | R6: 5 | T6: P3 | U6: 0.33 | V6: Professional
A7: P1-Business Systems Analysis Consultant Associate | B7: 4 | C7: 62.8 | D7: 70 | E7: 73.2 | F7: =IFERROR((C7-D7)/C7, "") -> -0.11464968 | G7: =IFERROR((D7-E7)/D7, "") -> -0.045714286 | H7: =(D7-D6)/D6 -> -0.51923077 | K7: 100006 | L7: 201.4 | N7: 100140 | O7: 130.5 | Q7: 100006 | R7: 1 | T7: P4 | U7: 0.21 | V7: Professional
A8: P2-Business Systems Analysis Consultant | B8: 4 | C8: 75.9 | D8: 84.275 | E8: 89.5 | F8: =IFERROR((C8-D8)/C8, "") -> -0.11034256 | G8: =IFERROR((D8-E8)/D8, "") -> -0.061999407 | H8: =(D8-D7)/D7 -> 0.20392857 | K8: 100007 | L8: 177.4 | N8: 100141 | O8: 226.9 | Q8: 100007 | R8: 2 | T8: P5 | U8: 0.07 | V8: Professional
A9: P3-Business Systems Analysis Consultant Senior | B9: 4 | C9: 99.4 | D9: 109.125 | E9: 117.5 | F9: =IFERROR((C9-D9)/C9, "") -> -0.097837022 | G9: =IFERROR((D9-E9)/D9, "") -> -0.07674685 | H9: =(D9-D8)/D8 -> 0.29486799 | K9: 100018 | L9: 58.270833 | N9: 101026 | O9: 82.9 | Q9: 100018 | R9: 72 | T9: M1 | U9: 0.13 | V9: Management
A10: P4-Business Systems Analysis Consultant Principal | B10: 3 | C10: 129.4 | D10: 131.8 | E10: 135.6 | F10: =IFERROR((C10-D10)/C10, "") -> -0.018547141 | G10: =IFERROR((D10-E10)/D10, "") -> -0.028831563 | H10: =(D10-D9)/D9 -> 0.20778923 | K10: 100019 | L10: 50.845312 | N10: 100394 | O10: 127.075 | Q10: 100019 | R10: 64 | T10: M2 | U10: 0.38 | V10: Management
A11: Data Governance | F11: =IFERROR((C11-D11)/C11, "") | G11: =IFERROR((D11-E11)/D11, "") | H11: =(D11-D10)/D10 -> -1 | K11: 100020 | L11: 66.03125 | N11: 100391 | O11: 171.96667 | Q11: 100020 | R11: 16 | T11: M3 | U11: 0.31 | V11: Management
A12: M2-Senior Manager Data Governance | B12: 3 | C12: 138.8 | D12: 146.8 | E12: 155.1 | F12: =IFERROR((C12-D12)/C12, "") -> -0.057636888 | G12: =IFERROR((D12-E12)/D12, "") -> -0.05653951 | H12: =(D12-D11)/D11 -> #DIV/0! | K12: 100021 | L12: 66 | N12: 100392 | O12: 223.26667 | Q12: 100021 | R12: 3 | T12: M4 | U12: =18% -> 0.18 | V12: Management
A13: M4-Senior Director Data Governance | B13: 2 | C13: 227.2 | D13: 231.8 | E13: 236.4 | F13: =IFERROR((C13-D13)/C13, "") -> -0.020246479 | G13: =IFERROR((D13-E13)/D13, "") -> -0.019844694 | H13: =(D13-D12)/D12 -> 0.57901907 | K13: 100022 | L13: 106.925 | N13: FI-AC-P1 | O13: 65.7 | Q13: 100022 | R13: 8
A14: P1-Data Governance Analyst Associate | B14: 3 | C14: 63.2 | D14: 66.833333 | E14: 73.7 | F14: =IFERROR((C14-D14)/C14, "") -> -0.057489451 | G14: =IFERROR((D14-E14)/D14, "") -> -0.10274314 | H14: =(D14-D13)/D13 -> -0.71167673 | K14: 100023 | L14: 85.508333 | N14: 100021 | O14: 75 | Q14: 100023 | R14: 12
A15: P2-Data Governance Analyst | B15: 3 | C15: 81.4 | D15: 85.633333 | E15: 88 | F15: =IFERROR((C15-D15)/C15, "") -> -0.052006552 | G15: =IFERROR((D15-E15)/D15, "") -> -0.027637213 | H15: =(D15-D14)/D14 -> 0.28129676 | K15: 100024 | L15: 91.613333 | N15: 100023 | O15: 95.325 | Q15: 100024 | R15: 15
A16: P3-Data Governance Analyst Senior | B16: 3 | C16: 107.9 | D16: 115.23333 | E16: 121.2 | F16: =IFERROR((C16-D16)/C16, "") -> -0.067964164 | G16: =IFERROR((D16-E16)/D16, "") -> -0.051778999 | H16: =(D16-D15)/D15 -> 0.34565979 | K16: 100025 | L16: 185.225 | N16: 100022 | O16: 114.775 | Q16: 100025 | R16: 8
A17: P4-Data Governance Analyst Principal | B17: 3 | C17: 108.4 | D17: 136.5 | E17: 153.9 | F17: =IFERROR((C17-D17)/C17, "") -> -0.25922509 | G17: =IFERROR((D17-E17)/D17, "") -> -0.12747253 | H17: =(D17-D16)/D16 -> 0.18455308 | K17: 100026 | L17: 86.871429 | N17: FI-AC-P5 | O17: 153.7 | Q17: 100026 | R17: 7
A18: Information Security | F18: =IFERROR((C18-D18)/C18, "") | G18: =IFERROR((D18-E18)/D18, "") | H18: =(D18-D17)/D17 -> -1 | K18: 100028 | L18: 99.22 | N18: FI-AP-M2 | O18: 145.3 | Q18: 100028 | R18: 5
A19: M3-Director Information Security | B19: 2 | C19: 191.9 | D19: 201.25 | E19: 210.6 | F19: =IFERROR((C19-D19)/C19, "") -> -0.048723293 | G19: =IFERROR((D19-E19)/D19, "") -> -0.046459627 | H19: =(D19-D18)/D18 -> #DIV/0! | K19: 100132 | L19: 143.28667 | N19: FI-AP-M4 | O19: 243.1 | Q19: 100132 | R19: 15
A20: M4-Senior Director Information Security | B20: 1 | C20: 228.3 | D20: 228.3 | E20: 228.3 | F20: =IFERROR((C20-D20)/C20, "") -> 0 | G20: =IFERROR((D20-E20)/D20, "") -> 0 | H20: =(D20-D19)/D19 -> 0.13440994 | K20: 100133 | L20: 165.58333 | N20: FI-AP-P3 | O20: 105.8 | Q20: 100133 | R20: 6
A21: P1-Information Security Consultant Associate | B21: 3 | C21: 76.1 | D21: 77.3 | E21: 78.6 | F21: =IFERROR((C21-D21)/C21, "") -> -0.015768725 | G21: =IFERROR((D21-E21)/D21, "") -> -0.016817594 | H21: =(D21-D20)/D20 -> -0.66141042 | K21: 100136 | L21: 84.45 | N21: FI-AP-P4 | O21: 185.6 | Q21: 100136 | R21: 2
A22: P2-Information Security Consultant | B22: 3 | C22: 94.4 | D22: 96.5 | E22: 100.1 | F22: =IFERROR((C22-D22)/C22, "") -> -0.022245763 | G22: =IFERROR((D22-E22)/D22, "") -> -0.037305699 | H22: =(D22-D21)/D21 -> 0.24838292 | K22: 100137 | L22: 157.6 | N22: FI-FP-M2 | O22: 141.85 | Q22: 100137 | R22: 3
A23: P3-Information Security Consultant Senior | B23: 2 | C23: 121.4 | D23: 124.1 | E23: 126.8 | F23: =IFERROR((C23-D23)/C23, "") -> -0.022240527 | G23: =IFERROR((D23-E23)/D23, "") -> -0.021756648 | H23: =(D23-D22)/D22 -> 0.28601036 | K23: 100138 | L23: 106.8375 | N23: FI-FP-M3 | O23: 199.575 | Q23: 100138 | R23: 8
A24: P4-Information Security Consultant Principal | B24: 2 | C24: 147.2 | D24: 148.35 | E24: 149.5 | F24: =IFERROR((C24-D24)/C24, "") -> -0.0078125 | G24: =IFERROR((D24-E24)/D24, "") -> -0.007751938 | H24: =(D24-D23)/D23 -> 0.19540693 | K24: 100140 | L24: 140.93333 | N24: FI-FP-M4 | O24: 237 | Q24: 100140 | R24: 3
A25: P5-Information Security Director | B25: 2 | C25: 175.2 | D25: 177.65 | E25: 180.1 | F25: =IFERROR((C25-D25)/C25, "") -> -0.013984018 | G25: =IFERROR((D25-E25)/D25, "") -> -0.013791162 | H25: =(D25-D24)/D24 -> 0.1975059 | K25: 100183 | L25: 72.35 | N25: 100388 | O25: 69.275 | Q25: 100183 | R25: 6
A26: IT Architecture | F26: =IFERROR((C26-D26)/C26, "") | G26: =IFERROR((D26-E26)/D26, "") | H26: =(D26-D25)/D25 -> -1 | K26: 100186 | L26: 84.521429 | N26: 100192 | O26: 82.325 | Q26: 100186 | R26: 14
A27: M4-Senior Director IT Architecture | B27: 2 | C27: 238.6 | D27: 251.2 | E27: 263.8 | F27: =IFERROR((C27-D27)/C27, "") -> -0.052808047 | G27: =IFERROR((D27-E27)/D27, "") -> -0.050159236 | H27: =(D27-D26)/D26 -> #DIV/0! | K27: 100187 | L27: 104.41 | N27: 100194 | O27: 103.825 | Q27: 100187 | R27: 20
A28: P3-IT Architect Senior | B28: 2 | C28: 136.8 | D28: 142.5 | E28: 148.2 | F28: =IFERROR((C28-D28)/C28, "") -> -0.041666667 | G28: =IFERROR((D28-E28)/D28, "") -> -0.04 | H28: =(D28-D27)/D27 -> -0.43272293 | K28: 100193 | L28: 128.58 | N28: 100193 | O28: 127.075 | Q28: 100193 | R28: 10
A29: P4-IT Architect Principal | B29: 3 | C29: 167.4 | D29: 168.6 | E29: 170.6 | F29: =IFERROR((C29-D29)/C29, "") -> -0.0071684588 | G29: =IFERROR((D29-E29)/D29, "") -> -0.011862396 | H29: =(D29-D28)/D28 -> 0.18315789 | K29: 100194 | L29: 87.333333 | N29: FI-FP-P5 | O29: 156.93333 | Q29: 100194 | R29: 3
A30: P5-IT Architect Director | B30: 2 | C30: 184.4 | D30: 190.25 | E30: 196.1 | F30: =IFERROR((C30-D30)/C30, "") -> -0.031724512 | G30: =IFERROR((D30-E30)/D30, "") -> -0.030749014 | H30: =(D30-D29)/D29 -> 0.12841044 | K30: 100199 | L30: 63.478261 | N30: FI-FR-P2 | O30: 80.325 | Q30: 100199 | R30: 23
A31: IT Development | F31: =IFERROR((C31-D31)/C31, "") | G31: =IFERROR((D31-E31)/D31, "") | H31: =(D31-D30)/D30 -> -1 | K31: 100201 | L31: 75.508333 | N31: FI-FR-P3 | O31: 100.83333 | Q31: 100201 | R31: 12
A32: M2-Senior Manager IT Development | B32: 1 | C32: 161.4 | D32: 161.4 | E32: 161.4 | F32: =IFERROR((C32-D32)/C32, "") -> 0 | G32: =IFERROR((D32-E32)/D32, "") -> 0 | H32: =(D32-D31)/D31 -> #DIV/0! | K32: 100202 | L32: 99.829412 | N32: FI-FR-M4 | O32: 226.6 | Q32: 100202 | R32: 17
A33: M3-Director IT Development | B33: 6 | C33: 188.1 | D33: 194.5 | E33: 205.5 | F33: =IFERROR((C33-D33)/C33, "") -> -0.034024455 | G33: =IFERROR((D33-E33)/D33, "") -> -0.05655527 | H33: =(D33-D32)/D32 -> 0.20508055 | K33: 100203 | L33: 184.1 | N33: FI-FR-M2 | O33: 136.63333 | Q33: 100203 | R33: 2
A34: P1-IT Developer Associate | B34: 4 | C34: 74.9 | D34: 80.625 | E34: 93.4 | F34: =IFERROR((C34-D34)/C34, "") -> -0.076435247 | G34: =IFERROR((D34-E34)/D34, "") -> -0.15844961 | H34: =(D34-D33)/D33 -> -0.58547558 | K34: 100249 | L34: 59.666667 | N34: FI-FS-M2 | O34: 139.65 | Q34: 100249 | R34: 3
A35: P2-IT Developer | B35: 4 | C35: 92.1 | D35: 99.125 | E35: 105.5 | F35: =IFERROR((C35-D35)/C35, "") -> -0.076275787 | G35: =IFERROR((D35-E35)/D35, "") -> -0.064312736 | H35: =(D35-D34)/D34 -> 0.22945736 | K35: 100250 | L35: 55.5 | N35: 100402 | O35: 82.2 | Q35: 100250 | R35: 3
A36: P3-IT Developer Senior | B36: 3 | C36: 117.8 | D36: 124.66667 | E36: 138 | F36: =IFERROR((C36-D36)/C36, "") -> -0.058290889 | G36: =IFERROR((D36-E36)/D36, "") -> -0.10695187 | H36: =(D36-D35)/D35 -> 0.25767129 | K36: 100263 | L36: 112.5 | N36: 100404 | O36: 106.35 | Q36: 100263 | R36: 2
A37: P4-IT Developer Principal | B37: 3 | C37: 140.7 | D37: 146.96667 | E37: 153.8 | F37: =IFERROR((C37-D37)/C37, "") -> -0.044539209 | G37: =IFERROR((D37-E37)/D37, "") -> -0.046495804 | H37: =(D37-D36)/D36 -> 0.17887701 | K37: 100271 | L37: 44.357143 | N37: 100002 | O37: 79.95 | Q37: 100271 | R37: 7
A38: IT Service Management | F38: =IFERROR((C38-D38)/C38, "") | G38: =IFERROR((D38-E38)/D38, "") | H38: =(D38-D37)/D37 -> -1 | K38: 100272 | L38: 49.4375 | N38: 100003 | O38: 102.65 | Q38: 100272 | R38: 8
